Workbook

Sheet Instruções e Resumo
A1: SESC PAULISTA — PROJETO COSMOCHÃO (v12.0)
A3: PLANILHA DE COTAÇÃO DE MATERIAIS, INSUMOS E SERVIÇOS
A5: ORIENTAÇÕES PARA PREENCHIMENTO E COTAÇÃO:
A6: 1. Esta planilha contém o levantamento quantitativo detalhado dos materiais, insumos e serviços da exposição CosmoChão.
A7: 2. NOTA DA v12.0: Adicionado fornecimento de vale-alimentação para a fase de galpão (+20,0 pessoa-dias / R$ 600,00).
A8: 3. Os fornecedores devem preencher EXCLUSIVAMENTE a coluna 'Custo Unitário (R$)' [células destacadas em AZUL CLARO].
A9: 4. Os valores totais por item, sub-totais por disciplina e o valor total geral são calculados AUTOMATICAMENTE.
A10: 5. No campo 'Observações do Fornecedor', informe a marca oferecida, prazos de entrega ou eventuais ressalvas técnicas.
A11: 6. O campo Status indica a origem do dado no projeto: EXPLÍCITO, DERIVADO, PENDENTE, DIVERGENTE, FECHADO ou REFORMADO.
A13: RESUMO CONSOLIDADO DA COTAÇÃO
A15: Indicador | B15: Valor / Status
A16: TOTAL GERAL COTADO (R$) | B16: ='Resumo por Disciplina'!D13 + 'Mão de Obra e Serviços'!G21 -> 197096.48
A17: Total de Itens Mapeados | B17: =COUNTA('Cotação de Materiais'!A4:A44) + COUNTA('Mão de Obra e Serviços'!A4:A20) -> 56
A18: Disciplinas Atendidas | B18: 10
A19: Legenda de Preenchimento | B19: Azul Claro = Campo Editável pelo Fornecedor | Verde = Cálculo Automático
A21: LEGENDA DOS STATUS DO LEVANTAMENTO
A22: Status | B22: Descrição / Conceito
A23: EXPLÍCITO | B23: Dado quantitativo ou especificação presente diretamente no memorial / desenho.
A24: DERIVADO | B24: Dado calculado matematicamente a partir de parâmetros das fontes (ex: consumo de tinta/ignífugo).
A25: PENDENTE | B25: Informação que depende de definição executiva, medição in loco ou cotação detalhada.
A26: DIVERGENTE | B26: Conflito identificado entre diferentes memoriais do projeto (ex: massas de lastro).
A27: FECHADO | B27: Item com cotação de mercado confirmada e fechada.
A28: REFORMADO | B28: Elemento existente no acervo do SESC que passará por tratamento, pintura ou restauração.
A31: COMO GERAR O PREÇO E O ANEXO III (v15)
A32: 1. Preencha os custos nas abas Cotação de Materiais e Mão de Obra e Serviços (azul claro), como sempre.
A33: 2. Na aba Rateio Anexo, diga para qual item do Anexo vai cada linha de custo (Item Anexo + Base). Frete, ART, supervisão = INDIRETO.
A34: 3. Confira: coluna "Rateio no Anexo (%)" das abas de custo tem que dar 100% (vermelho = falta ratear).
A35: 4. Na aba Precificação, digite o PREÇO FINAL DESEJADO e o % da sobra que vai pro material (padrão 50%). A MO compensa sozinha.
A36: 5. A aba Anexo III sai pronta, com unitários em centavos e total fechando no preço. Itens "SEM CUSTO" em vermelho = falta linha de custo.
A37: 6. Preencher a oficial do Sesc: na aba Anexo III, coluna M mostra cada bloco (ex.: F10:G13). Copie o bloco e cole na mesma faixa da oficial com COLAR ESPECIAL > VALORES. Nunca colar normal (cria vínculo externo).

Sheet Precificação
A1: PRECIFICAÇÃO — CUSTO → PREÇO DE VENDA → ANEXO III
A2: Azul = você digita | Verde = calcula sozinho | Amarelo = resultado principal
A3: Parâmetro | B3: Valor | C3: Como funciona
A4: Custo de material (R$) | B4: ='Cotação de Materiais'!H45 -> 78534.481 | C4: Soma da aba Cotação de Materiais.
A5: Custo de MO + serviços + logística (R$) | B5: ='Mão de Obra e Serviços'!G21 -> 118562 | C5: Soma da aba Mão de Obra e Serviços (inclui frete, alimentação, ART).
A6: CUSTO TOTAL (R$) | B6: =B4+B5 -> 197096.48 | C6: Motor de partida: tudo sai daqui.
A8: PREÇO FINAL DESEJADO (R$) | B8: 339500 | C8: Digite o preço que você quer fechar. O Anexo III fecha exatamente nesse valor.
A9: Sobra sobre o custo (R$) | B9: =B8-B6 -> 142403.52 | C9: Preço desejado − custo total. É isso que vai ser dividido entre material e MO.
A10: Markup total sobre o custo | B10: =IF(B6=0,0,B8/B6-1) -> 0.72250665 | C10: Quanto o preço está acima do custo, no geral.
A12: % DA SOBRA QUE VAI PRO MATERIAL | B12: 0.5 | C12: Começa em 50%. Achou o material caro? Baixe aqui — a MO compensa sozinha e o total não muda.
A13: % da sobra que vai pra MO | B13: =1-B12 -> 0.5 | C13: Automático: 100% − o que foi pro material.
A15: Acréscimo no material (R$) | B15: =B9*B12 -> 71201.759
A16: Acréscimo na MO (R$) | B16: =B9*B13 -> 71201.759
A17: Acréscimo % sobre o custo de material | B17: =IF(B4=0,0,B15/B4) -> 0.90663054 | C17: Esse % é aplicado no custo de material de TODOS os itens.
A18: Acréscimo % sobre o custo de MO | B18: =IF(B5=0,0,B16/B5) -> 0.60054452 | C18: Esse % é aplicado no custo de MO de TODOS os itens.
A19: Fator material | B19: =1+B17 -> 1.9066305 | C19: Custo de material × fator = venda de material.
A20: Fator MO | B20: =1+B18 -> 1.6005445 | C20: Custo de MO × fator = venda de MO.
A22: Venda de material (R$) | B22: =B4*B19 -> 149736.24
A23: Venda de MO (R$) | B23: =B5*B20 -> 189763.76
A24: VENDA TOTAL (R$) | B24: =B22+B23 -> 339500 | C24: Tem que ser igual ao preço desejado.
A26: Item que absorve os centavos (qtd = 1) | B26: A.7.5 | C26: Arredondar unitário pra centavo gera sobra de centavos. Ela vai pra MO deste item. Use um item com quantidade 1.
A27: Centavos de arredondamento (R$) | B27: ='Anexo III'!F3 -> -0.42 | C27: Normalmente centavos. Vermelho (mais de R$ 5) = confira o rateio.
A28: Total do Anexo III (R$) | B28: ='Anexo III'!K3 -> 339500
A29: Anexo III fecha no preço desejado? | B29: =IF(AND(ABS(B28-B8)<0.005,B30=0),"SIM","NÃO — confira") -> SIM | C29: SIM só se o total bate E todo o custo chegou nos itens do Anexo.
A30: Custo que NÃO chegou nos itens do Anexo (R$) | B30: =ROUND(B6-'Anexo III'!R3,2) -> 0 | C30: Tem que ser zero. Se não for: linha de custo sem destino ou com item errado na aba Rateio Anexo (coluna M e colunas "Rateio no Anexo" em vermelho).
A31: Itens do Anexo SEM CUSTO | B31: =COUNTIF('Anexo III'!L8:L400,"SEM CUSTO*") -> 2 | C31: Itens do Sesc sem nenhuma linha de custo: vão sair com preço zero. Crie a linha de custo e rateie.
A32: Qtd do item de centavos | B32: =IFERROR(INDEX('Anexo III'!E8:E400,MATCH(B26,'Anexo III'!B8:B400,0)),"NÃO ACHEI") -> 1 | C32: Tem que ser 1.
A34: POR DISCIPLINA (mesmo % em todas; o total fecha no preço desejado)
A35: Disciplina | B35: Custo material | C35: Custo MO | D35: Custo total | E35: % acrésc. material | F35: Venda material | G35: % acrésc. MO | H35: Venda MO | I35: Venda total | J35: % da venda
A36: Marcenaria e Cenotecnia | B36: =SUMIF('Cotação de Materiais'!$B$4:$B$200,A36,'Cotação de Materiais'!$H$4:$H$200) -> 21347.26 | C36: =SUMIF('Mão de Obra e Serviços'!$I$4:$I$200,A36,'Mão de Obra e Serviços'!$G$4:$G$200) -> 48200 | D36: =B36+C36 -> 69547.26 | E36: =$B$17 -> 0.90663054 | F36: =B36*$B$19 -> 40701.338 | G36: =$B$18 -> 0.60054452 | H36: =C36*$B$20 -> 77146.246 | I36: =F36+H36 -> 117847.58 | J36: =IF($I$47=0,0,I36/$I$47) -> 0.34712101
A37: Serralheria e Estruturas Metálicas | B37: =SUMIF('Cotação de Materiais'!$B$4:$B$200,A37,'Cotação de Materiais'!$H$4:$H$200) -> 6546.25 | C37: =SUMIF('Mão de Obra e Serviços'!$I$4:$I$200,A37,'Mão de Obra e Serviços'!$G$4:$G$200) -> 5000 | D37: =B37+C37 -> 11546.25 | E37: =$B$17 -> 0.90663054 | F37: =B37*$B$19 -> 12481.28 | G37: =$B$18 -> 0.60054452 | H37: =C37*$B$20 -> 8002.7226 | I37: =F37+H37 -> 20484.003 | J37: =IF($I$47=0,0,I37/$I$47) -> 0.060335796
A38: Elétrica e Iluminação | B38: =SUMIF('Cotação de Materiais'!$B$4:$B$200,A38,'Cotação de Materiais'!$H$4:$H$200) -> 9176.262 | C38: =SUMIF('Mão de Obra e Serviços'!$I$4:$I$200,A38,'Mão de Obra e Serviços'!$G$4:$G$200) -> 7000 | D38: =B38+C38 -> 16176.262 | E38: =$B$17 -> 0.90663054 | F38: =B38*$B$19 -> 17495.741 | G38: =$B$18 -> 0.60054452 | H38: =C38*$B$20 -> 11203.812 | I38: =F38+H38 -> 28699.553 | J38: =IF($I$47=0,0,I38/$I$47) -> 0.084534766
A39: Pintura e Acabamentos | B39: =SUMIF('Cotação de Materiais'!$B$4:$B$200,A39,'Cotação de Materiais'!$H$4:$H$200) -> 6741.02 | C39: =SUMIF('Mão de Obra e Serviços'!$I$4:$I$200,A39,'Mão de Obra e Serviços'!$G$4:$G$200) -> 27961 | D39: =B39+C39 -> 34702.02 | E39: =$B$17 -> 0.90663054 | F39: =B39*$B$19 -> 12852.635 | G39: =$B$18 -> 0.60054452 | H39: =C39*$B$20 -> 44752.825 | I39: =F39+H39 -> 57605.46 | J39: =IF($I$47=0,0,I39/$I$47) -> 0.16967735
A40: Vidros e Acrílicos | B40: =SUMIF('Cotação de Materiais'!$B$4:$B$200,A40,'Cotação de Materiais'!$H$4:$H$200) -> 1376.71 | C40: =SUMIF('Mão de Obra e Serviços'!$I$4:$I$200,A40,'Mão de Obra e Serviços'!$G$4:$G$200) -> 0 | D40: =B40+C40 -> 1376.71 | E40: =$B$17 -> 0.90663054 | F40: =B40*$B$19 -> 2624.8773 | G40: =$B$18 -> 0.60054452 | H40: =C40*$B$20 -> 0 | I40: =F40+H40 -> 2624.8773 | J40: =IF($I$47=0,0,I40/$I$47) -> 0.0077315975
A41: Comunicação Visual | B41: =SUMIF('Cotação de Materiais'!$B$4:$B$200,A41,'Cotação de Materiais'!$H$4:$H$200) -> 13681.459 | C41: =SUMIF('Mão de Obra e Serviços'!$I$4:$I$200,A41,'Mão de Obra e Serviços'!$G$4:$G$200) -> 1500 | D41: =B41+C41 -> 15181.459 | E41: =$B$17 -> 0.90663054 | F41: =B41*$B$19 -> 26085.488 | G41: =$B$18 -> 0.60054452 | H41: =C41*$B$20 -> 2400.8168 | I41: =F41+H41 -> 28486.305 | J41: =IF($I$47=0,0,I41/$I$47) -> 0.083906641
A42: Segurança Contra Incêndio | B42: =SUMIF('Cotação de Materiais'!$B$4:$B$200,A42,'Cotação de Materiais'!$H$4:$H$200) -> 10636.92 | C42: =SUMIF('Mão de Obra e Serviços'!$I$4:$I$200,A42,'Mão de Obra e Serviços'!$G$4:$G$200) -> 0 | D42: =B42+C42 -> 10636.92 | E42: =$B$17 -> 0.90663054 | F42: =B42*$B$19 -> 20280.677 | G42: =$B$18 -> 0.60054452 | H42: =C42*$B$20 -> 0 | I42: =F42+H42 -> 20280.677 | J42: =IF($I$47=0,0,I42/$I$47) -> 0.059736897
A43: Ferragens e Ancoragens | B43: =SUMIF('Cotação de Materiais'!$B$4:$B$200,A43,'Cotação de Materiais'!$H$4:$H$200) -> 7048.6 | C43: =SUMIF('Mão de Obra e Serviços'!$I$4:$I$200,A43,'Mão de Obra e Serviços'!$G$4:$G$200) -> 0 | D43: =B43+C43 -> 7048.6 | E43: =$B$17 -> 0.90663054 | F43: =B43*$B$19 -> 13439.076 | G43: =$B$18 -> 0.60054452 | H43: =C43*$B$20 -> 0 | I43: =F43+H43 -> 13439.076 | J43: =IF($I$47=0,0,I43/$I$47) -> 0.039584907
A44: Elementos Reformados | B44: =SUMIF('Cotação de Materiais'!$B$4:$B$200,A44,'Cotação de Materiais'!$H$4:$H$200) -> 1980 | C44: =SUMIF('Mão de Obra e Serviços'!$I$4:$I$200,A44,'Mão de Obra e Serviços'!$G$4:$G$200) -> 0 | D44: =B44+C44 -> 1980 | E44: =$B$17 -> 0.90663054 | F44: =B44*$B$19 -> 3775.1285 | G44: =$B$18 -> 0.60054452 | H44: =C44*$B$20 -> 0 | I44: =F44+H44 -> 3775.1285 | J44: =IF($I$47=0,0,I44/$I$47) -> 0.011119672
A45: Serviços Gerais e Manutenção | B45: =SUMIF('Cotação de Materiais'!$B$4:$B$200,A45,'Cotação de Materiais'!$H$4:$H$200) -> 0 | C45: =SUMIF('Mão de Obra e Serviços'!$I$4:$I$200,A45,'Mão de Obra e Serviços'!$G$4:$G$200) -> 8100 | D45: =B45+C45 -> 8100 | E45: =$B$17 -> 0.90663054 | F45: =B45*$B$19 -> 0 | G45: =$B$18 -> 0.60054452 | H45: =C45*$B$20 -> 12964.411 | I45: =F45+H45 -> 12964.411 | J45: =IF($I$47=0,0,I45/$I$47) -> 0.038186776
A46: Logística e Indiretos | B46: =SUMIF('Cotação de Materiais'!$B$4:$B$200,A46,'Cotação de Materiais'!$H$4:$H$200) -> 0 | C46: =SUMIF('Mão de Obra e Serviços'!$I$4:$I$200,A46,'Mão de Obra e Serviços'!$G$4:$G$200) -> 20801 | D46: =B46+C46 -> 20801 | E46: =$B$17 -> 0.90663054 | F46: =B46*$B$19 -> 0 | G46: =$B$18 -> 0.60054452 | H46: =C46*$B$20 -> 33292.927 | I46: =F46+H46 -> 33292.927 | J46: =IF($I$47=0,0,I46/$I$47) -> 0.098064585
...

Sheet Cotação de Materiais
A1: COTAÇÃO DE MATERIAIS E INSUMOS — SESC PAULISTA (COSMOCHÃO v12.0)
A3: Item | B3: Disciplina | C3: Material / Elemento | D3: Especificação Técnica | E3: Quantidade | F3: Unidade | G3: Custo Unitário (R$) | H3: Custo Total (R$) | I3: Status | J3: Aplicação / Local | K3: Observações do Fornecedor / Marca | L3: Rateio no Anexo (%)
A4: MAT-01 | B4: Marcenaria e Cenotecnia | C4: Chapas de MDF Comum 18mm | D4: Chapa de MDF Comum / Cru 18mm (2,75 x 1,85 m) — Ignifugação posterior c/ CKC-2020 | E4: 302 | F4: m² | G4: 51.68 | H4: =IFERROR(E4*G4, 0) -> 15607.36 | I4: EXPLÍCITO | J4: Painéis P01-P07, PR01 (48,5m²), PR02 (48,5m²) e bases M06-M18, M22, M26, M27 | K4: Leo Madeiras R$ 262,90/chapa = R$ 51,68/m² (60 chapas) | L4: =SUMIFS('Rateio Anexo'!$H$6:$H$600,'Rateio Anexo'!$A$6:$A$600,A4,'Rateio Anexo'!$M$6:$M$600,"") -> 1
A5: MAT-02 | B5: Marcenaria e Cenotecnia | C5: Chapas de MDF Comum 10mm | D5: Chapa de MDF Comum / Cru 10mm — Ignifugação posterior c/ CKC-2020 | E5: 45 | F5: m² | G5: 33.42 | H5: =IFERROR(E5*G5, 0) -> 1503.9 | I5: PENDENTE | J5: Estações M19-M21, M24, Carrinho M23 e Caixa M25 | K5: MDF Comum 10mm — R$ 170,00/chapa = R$ 33,42/m² (~9 chapas) | L5: =SUMIFS('Rateio Anexo'!$H$6:$H$600,'Rateio Anexo'!$A$6:$A$600,A5,'Rateio Anexo'!$M$6:$M$600,"") -> 1
A6: MAT-03 | B6: Marcenaria e Cenotecnia | C6: Chapas de MDF Comum 6mm e 15mm | D6: Chapas de MDF Comum / Cru 6mm (R$ 118,90) e 15mm (R$ 218,90) — Média ponderada R$ 33,20/m² | E6: 30 | F6: m² | G6: 33.2 | H6: =IFERROR(E6*G6, 0) -> 996 | I6: PENDENTE | J6: Tampo da Mesa M01 e bases escultóricas M02-M05 | K6: 15m² de 6mm (~3 chapas) + 15m² de 15mm (~3 chapas) | L6: =SUMIFS('Rateio Anexo'!$H$6:$H$600,'Rateio Anexo'!$A$6:$A$600,A6,'Rateio Anexo'!$M$6:$M$600,"") -> 1
A7: MAT-04 | B7: Marcenaria e Cenotecnia | C7: Pontaletes de Madeira | D7: Seção de 5 x 5 cm em madeira para estrutura interna | E7: 180 | F7: m | G7: 18 | H7: =IFERROR(E7*G7, 0) -> 3240 | I7: DERIVADO | J7: Estrutura interna de P01-P06, PR01, PR02, M02-M05, M13 | K7: Sarrafo de pinus/cedrinho 5x5cm (R$ 18,00/m) | L7: =SUMIFS('Rateio Anexo'!$H$6:$H$600,'Rateio Anexo'!$A$6:$A$600,A7,'Rateio Anexo'!$M$6:$M$600,"") -> 1
A8: MET-01 | B8: Serralheria e Estruturas Metálicas | C8: Perfis Tubulares S03 | D8: Tubo de aço 50 x 50 x 5,0 mm (7,07 kg/m) | E8: 47 | F8: m | G8: 70 | H8: =IFERROR(E8*G8, 0) -> 3290 | I8: PENDENTE | J8: Estrutura metálica interna da Base M27 (Obra Solange Pessoa) | K8: 47m de tubo = 332,29 kg de aço | L8: =SUMIFS('Rateio Anexo'!$H$6:$H$600,'Rateio Anexo'!$A$6:$A$600,A8,'Rateio Anexo'!$M$6:$M$600,"") -> 1
A9: MET-02 | B9: Serralheria e Estruturas Metálicas | C9: Tubos de Aço Estrutural | D9: Tubo de aço 50 x 50 x 3,0 mm (4,43 kg/m) | E9: 25 | F9: m | G9: 45.85 | H9: =IFERROR(E9*G9, 0) -> 1146.25 | I9: DERIVADO | J9: 4 Barracudas S01 (P05) e 4 Barracudas Piso-Teto (Obra Davi) | K9: 25m de tubo = 110,75 kg de aço (Barra 6m R$ 275,08) | L9: =SUMIFS('Rateio Anexo'!$H$6:$H$600,'Rateio Anexo'!$A$6:$A$600,A9,'Rateio Anexo'!$M$6:$M$600,"") -> 1
A10: MET-03 | B10: Serralheria e Estruturas Metálicas | C10: Molduras Metálicas S01 | D10: Metalon 50 x 50 mm (37 x 93 cm) c/ sapata e contrapesos | E10: 2 | F10: un | G10: 450 | H10: =IFERROR(E10*G10, 0) -> 900 | I10: EXPLÍCITO | J10: Caixas de marcenaria S01 / Reforço P05 (Obra Davi) | K10: Conjunto de 2 molduras S01 | L10: =SUMIFS('Rateio Anexo'!$H$6:$H$600,'Rateio Anexo'!$A$6:$A$600,A10,'Rateio Anexo'!$M$6:$M$600,"") -> 1
A11: MET-04 | B11: Serralheria e Estruturas Metálicas | C11: Mão-Francesa Metálica S02 | D11: Tubo 50 x 50 mm e chapa maciça 3 mm (40 x 40 cm) | E11: 2 | F11: un | G11: 280 | H11: =IFERROR(E11*G11, 0) -> 560 | I11: EXPLÍCITO | J11: Sustentação do barco no Painel P05 | K11: Conjunto de 2 mãos-francesas S02 | L11: =SUMIFS('Rateio Anexo'!$H$6:$H$600,'Rateio Anexo'!$A$6:$A$600,A11,'Rateio Anexo'!$M$6:$M$600,"") -> 1
A12: MET-05 | B12: Serralheria e Estruturas Metálicas | C12: Placas de Apoio de Aço | D12: Chapa de aço 100 x 100 x 5 mm c/ barra roscada e contraporca | E12: 8 | F12: un | G12: 65 | H12: =IFERROR(E12*G12, 0) -> 520 | I12: EXPLÍCITO | J12: Extremidades das 4 barracudas piso-teto (Obra Davi) | K12: Placas de fixação superior e inferior | L12: =SUMIFS('Rateio Anexo'!$H$6:$H$600,'Rateio Anexo'!$A$6:$A$600,A12,'Rateio Anexo'!$M$6:$M$600,"") -> 1
A13: MET-06 | B13: Serralheria e Estruturas Metálicas | C13: Perfis de Alumínio de Canto | D13: Perfil de sobrepor 16 x 16 mm (L = 180 cm) para LED c/ difusor | E13: 2 | F13: un | G13: 65 | H13: =IFERROR(E13*G13, 0) -> 130 | I13: PENDENTE | J13: Nichos superior e inferior da Vitrine M22 (Francisco Brennand) | K13: Perfil de alumínio 16x16mm + difusor PMMA | L13: =SUMIFS('Rateio Anexo'!$H$6:$H$600,'Rateio Anexo'!$A$6:$A$600,A13,'Rateio Anexo'!$M$6:$M$600,"") -> 1
A14: ELE-01 | B14: Elétrica e Iluminação | C14: Quadro QDLF-Temporário | D14: Caixa de sobrepor 3F+N+T (220/127V), barramento 80A | E14: 1 | F14: un | G14: 1850 | H14: =IFERROR(E14*G14, 0) -> 1850 | I14: PENDENTE | J14: Quadro provisório de distribuição no 5º andar | K14: Quadro provisório completo com barramento 80A | L14: =SUMIFS('Rateio Anexo'!$H$6:$H$600,'Rateio Anexo'!$A$6:$A$600,A14,'Rateio Anexo'!$M$6:$M$600,"") -> 1
A15: ELE-02 | B15: Elétrica e Iluminação | C15: Cabo Alimentador Geral | D15: Cabo flexível Afumex 0,6/1kV 90°C (3#10 + N10 + PE10 mm²) | E15: 45 | F15: m | G15: 14.67 | H15: =IFERROR(E15*G15, 0) -> 660.15 | I15: EXPLÍCITO | J15: Interligação do QG-N-05 PV ao QDLF-Temporário | K15: Cabo Prysmian Afumex 10 mm² (R$ 14,67/m) | L15: =SUMIFS('Rateio Anexo'!$H$6:$H$600,'Rateio Anexo'!$A$6:$A$600,A15,'Rateio Anexo'!$M$6:$M$600,"") -> 1
... A44: MOB-03 | B44: Elementos Reformados | C44: Mesa Tátil | D44: Repintura acrílica na cor Terra Roxa c/ vinil de recorte | E44: 1 | F44: un | G44: 180 | H44: =IFERROR(E44*G44, 0) -> 180 | I44: REFORMADO | J44: Espaço Educativo | K44: Repintura e vinil de recorte | L44: =SUMIFS('Rateio Anexo'!$H$6:$H$600,'Rateio Anexo'!$A$6:$A$600,A44,'Rateio Anexo'!$M$6:$M$600,"") -> 1
A45: TOTAL GERAL | G45: TOTAL: | H45: =SUM(H4:H44) -> 78534.481

Sheet Mão de Obra e Serviços
A1: COTAÇÃO E REGISTRO DE MÃO DE OBRA, SERVIÇOS E LOGÍSTICA — SESC PAULISTA (COSMOCHÃO v12.0)
A3: Item | B3: Categoria / Função | C3: Especificação / Escopo | D3: Quantidade Est. | E3: Unidade | F3: Valor Unitário (R$) | G3: Custo Total (R$) | H3: Status | I3: Disciplina | J3: Rateio no Anexo (%)
A4: MO-01 | B4: Pintura por empreita — mão de obra | C4: Pintura acrílica de painéis novos (P01–P07, PR01, PR02), existentes e móveis (Preço Fechado / Empreita c/ supervisor embutido) | D4: 559.22 | E4: m² | F4: 50 | G4: =IFERROR(D4*F4, 0) -> 27961 | H4: EXPLÍCITO | I4: Pintura e Acabamentos | J4: =SUMIFS('Rateio Anexo'!$H$6:$H$600,'Rateio Anexo'!$A$6:$A$600,A4,'Rateio Anexo'!$M$6:$M$600,"") -> 1
A5: MO-02A | B5: Marceneiro / Cenotécnico (Galpão) | C5: Equipe de 4 marceneiros alocada por 5 dias de pré-fabricação no galpão (4 p x 5 dias) | D5: 20 | E5: pessoa-dia | F5: 250 | G5: =IFERROR(D5*F5, 0) -> 5000 | H5: EXPLÍCITO | I5: Marcenaria e Cenotecnia | J5: =SUMIFS('Rateio Anexo'!$H$6:$H$600,'Rateio Anexo'!$A$6:$A$600,A5,'Rateio Anexo'!$M$6:$M$600,"") -> 1
A6: MO-02B | B6: Marceneiro / Cenotécnico (SESC) | C6: Equipe de 8 marceneiros alocada nos 20 dias de montagem no SESC (8 p x 20 dias) | D6: 160 | E6: pessoa-dia | F6: 270 | G6: =IFERROR(D6*F6, 0) -> 43200 | H6: EXPLÍCITO | I6: Marcenaria e Cenotecnia | J6: =SUMIFS('Rateio Anexo'!$H$6:$H$600,'Rateio Anexo'!$A$6:$A$600,A6,'Rateio Anexo'!$M$6:$M$600,"") -> 1
A7: MO-03 | B7: Ajudante, carga e descarga | C7: 4 ajudantes nos 2 primeiros dias de montagem no SESC (8 p-d) e no dia da desmontagem (4 p-d) | D7: 10 | E7: pessoa-dia | F7: 130 | G7: =IFERROR(D7*F7, 0) -> 1300 | H7: EXPLÍCITO | I7: Logística e Indiretos | J7: =SUMIFS('Rateio Anexo'!$H$6:$H$600,'Rateio Anexo'!$A$6:$A$600,A7,'Rateio Anexo'!$M$6:$M$600,"") -> 1
A8: MO-04 | B8: Equipe de Limpeza | C8: 3 pessoas alocadas nos últimos 3 dias de montagem no SESC para limpeza fina pré-abertura | D8: 9 | E8: pessoa-dia | F8: 100 | G8: =IFERROR(D8*F8, 0) -> 900 | H8: EXPLÍCITO | I8: Serviços Gerais e Manutenção | J8: =SUMIFS('Rateio Anexo'!$H$6:$H$600,'Rateio Anexo'!$A$6:$A$600,A8,'Rateio Anexo'!$M$6:$M$600,"") -> 1
A9: MO-05 | B9: Serralheiro — EMPREITA | C9: Montagem e ajustes de estruturas metálicas S01, S02, S03 e barracudas (Preço Fechado / Empreita) | D9: 1 | E9: cj | F9: 5000 | G9: =IFERROR(D9*F9, 0) -> 5000 | H9: FECHADO | I9: Serralheria e Estruturas Metálicas | J9: =SUMIFS('Rateio Anexo'!$H$6:$H$600,'Rateio Anexo'!$A$6:$A$600,A9,'Rateio Anexo'!$M$6:$M$600,"") -> 1
A10: MO-06 | B10: Supervisor de Montagem | C10: 1 supervisor dedicado durante toda a montagem no SESC (20 dias); supervisão de pintura e elétrica embutida nas empreitas | D10: 20 | E10: dia | F10: 300 | G10: =IFERROR(D10*F10, 0) -> 6000 | H10: EXPLÍCITO | I10: Logística e Indiretos | J10: =SUMIFS('Rateio Anexo'!$H$6:$H$600,'Rateio Anexo'!$A$6:$A$600,A10,'Rateio Anexo'!$M$6:$M$600,"") -> 1
A11: MO-07 | B11: Tapeceiro | C11: Serviços de tapeçaria, estofamento e revestimentos têxteis | D11: 5 | E11: pessoa-dia | F11: 1 | G11: =IFERROR(D11*F11, 0) -> 5 | H11: PENDENTE | I11: Logística e Indiretos | J11: =SUMIFS('Rateio Anexo'!$H$6:$H$600,'Rateio Anexo'!$A$6:$A$600,A11,'Rateio Anexo'!$M$6:$M$600,"") -> 1
A12: MO-08 | B12: Adesivador | C12: 2 pessoas alocadas por 3 dias para aplicação de insulfilm e vinil de recorte | D12: 6 | E12: pessoa-dia | F12: 250 | G12: =IFERROR(D12*F12, 0) -> 1500 | H12: EXPLÍCITO | I12: Comunicação Visual | J12: =SUMIFS('Rateio Anexo'!$H$6:$H$600,'Rateio Anexo'!$A$6:$A$600,A12,'Rateio Anexo'!$M$6:$M$600,"") -> 1
A13: MO-09 | B13: Eletricista — EMPREITA | C13: Instalação do QDLF-Temporário, fiação, iluminação LED M01/M22 (Preço Fechado / Empreita c/ supervisor embutido) | D13: 1 | E13: cj | F13: 7000 | G13: =IFERROR(D13*F13, 0) -> 7000 | H13: FECHADO | I13: Elétrica e Iluminação | J13: =SUMIFS('Rateio Anexo'!$H$6:$H$600,'Rateio Anexo'!$A$6:$A$600,A13,'Rateio Anexo'!$M$6:$M$600,"") -> 1
A14: MO-10 | B14: Equipe de Manutenção Expositiva | C14: Visitas quinzenais durante os 8 meses de exposição com equipe dedicada de 2 pessoas (18 visitas x 2 p) | D14: 36 | E14: pessoa-dia | F14: 200 | G14: =IFERROR(D14*F14, 0) -> 7200 | H14: DERIVADO | I14: Serviços Gerais e Manutenção | J14: =SUMIFS('Rateio Anexo'!$H$6:$H$600,'Rateio Anexo'!$A$6:$A$600,A14,'Rateio Anexo'!$M$6:$M$600,"") -> 1
A15: LOG-01A | B15: Alimentação (Campo SESC) | C15: Vale-alimentação para equipe operacional durante atuação em campo no SESC (212 pessoa-dias de campo) | D15: 212 | E15: pessoa-dia | F15: 28 | G15: =IFERROR(D15*F15, 0) -> 5936 | H15: DERIVADO | I15: Logística e Indiretos | J15: =SUMIFS('Rateio Anexo'!$H$6:$H$600,'Rateio Anexo'!$A$6:$A$600,A15,'Rateio Anexo'!$M$6:$M$600,"") -> 1
... A20: ENG-01 | B20: ART — referência interna | C20: Anotação de Responsabilidade Técnica de engenharia civil/mecânica | D20: 1 | E20: registro | F20: 1500 | G20: =IFERROR(D20*F20, 0) -> 1500 | H20: EXPLÍCITO | I20: Logística e Indiretos | J20: =SUMIFS('Rateio Anexo'!$H$6:$H$600,'Rateio Anexo'!$A$6:$A$600,A20,'Rateio Anexo'!$M$6:$M$600,"") -> 1
B21: TOTAL DE MÃO DE OBRA, SERVIÇOS E LOGÍSTICA | G21: =SUM(G4:G20) -> 118562

Sheet Rateio Anexo
A1: RATEIO — DE ONDE VEM O CUSTO DE CADA ITEM DO ANEXO
A2: Cada linha de custo (MAT-xx / MO-xx) é dividida entre itens do Anexo pelo PESO (base × fator). Item "INDIRETO" = frete, ART, supervisão etc.: é espalhado nos itens proporcional ao custo direto.
A3: Total rateado (R$) | C3: =SUM(K6:K600) -> 197096.48 | E3: Indireto material (R$) | G3: =SUMIFS(K6:K600,D6:D600,"INDIRETO",B6:B600,"MAT") -> 280 | I3: Indireto MO (R$) | K3: =SUMIFS(K6:K600,D6:D600,"INDIRETO",B6:B600,"MO") -> 20367.667
A5: Código custo | B5: Tipo | C5: Descrição do custo | D5: Item Anexo | E5: Base | F5: Fator | G5: Peso | H5: % do custo | I5: Custo da linha | K5: Custo rateado | L5: Base do peso (de onde saiu) | M5: Conferência
A6: MAT-01 | B6: =IF($A6="","",IF(ISNUMBER(MATCH($A6,'Cotação de Materiais'!$A$4:$A$200,0)),"MAT",IF(ISNUMBER(MATCH($A6,'Mão de Obra e Serviços'!$A$4:$A$200,0)),"MO","CÓDIGO?"))) -> MAT | C6: =IF($A6="","",IFERROR(INDEX('Cotação de Materiais'!$C$4:$C$200,MATCH($A6,'Cotação de Materiais'!$A$4:$A$200,0)),IFERROR(INDEX('Mão de Obra e Serviços'!$B$4:$B$200,MATCH($A6,'Mão de Obra e Serviços'!$A$4:$A$200,0)),""))) -> Chapas de MDF Comum 18mm | D6: A.2.1 | E6: 14 | F6: 1 | G6: =IF($A6="","",E6*IF(F6="",1,F6)) -> 14 | H6: =IF($A6="","",IF(SUMIF($A$6:$A$600,$A6,$G$6:$G$600)=0,0,G6/SUMIF($A$6:$A$600,$A6,$G$6:$G$600))) -> 0.035194449 | I6: =IF($A6="","",IFERROR(INDEX('Cotação de Materiais'!$H$4:$H$200,MATCH($A6,'Cotação de Materiais'!$A$4:$A$200,0)),IFERROR(INDEX('Mão de Obra e Serviços'!$G$4:$G$200,MATCH($A6,'Mão de Obra e Serviços'!$A$4:$A$200,0)),0))) -> 15607.36 | K6: =IF($A6="","",I6*H6) -> 549.29244 | L6: m² (painel = Anexo; base = envoltória) | M6: =IF($A6="","",IF(B6="CÓDIGO?","CÓDIGO NÃO ACHADO",IF($D6="","FALTA ITEM DO ANEXO",IF($D6="INDIRETO","",IF(COUNTIFS('Anexo III'!$B$8:$B$400,$D6,'Anexo III'!$E$8:$E$400,">0")=0,"ITEM NÃO ACHADO NO ANEXO","")))))
A7: MAT-01 | B7: =IF($A7="","",IF(ISNUMBER(MATCH($A7,'Cotação de Materiais'!$A$4:$A$200,0)),"MAT",IF(ISNUMBER(MATCH($A7,'Mão de Obra e Serviços'!$A$4:$A$200,0)),"MO","CÓDIGO?"))) -> MAT | C7: =IF($A7="","",IFERROR(INDEX('Cotação de Materiais'!$C$4:$C$200,MATCH($A7,'Cotação de Materiais'!$A$4:$A$200,0)),IFERROR(INDEX('Mão de Obra e Serviços'!$B$4:$B$200,MATCH($A7,'Mão de Obra e Serviços'!$A$4:$A$200,0)),""))) -> Chapas de MDF Comum 18mm | D7: A.2.2 | E7: 11.8 | F7: 1 | G7: =IF($A7="","",E7*IF(F7="",1,F7)) -> 11.8 | H7: =IF($A7="","",IF(SUMIF($A$6:$A$600,$A7,$G$6:$G$600)=0,0,G7/SUMIF($A$6:$A$600,$A7,$G$6:$G$600))) -> 0.029663893 | I7: =IF($A7="","",IFERROR(INDEX('Cotação de Materiais'!$H$4:$H$200,MATCH($A7,'Cotação de Materiais'!$A$4:$A$200,0)),IFERROR(INDEX('Mão de Obra e Serviços'!$G$4:$G$200,MATCH($A7,'Mão de Obra e Serviços'!$A$4:$A$200,0)),0))) -> 15607.36 | K7: =IF($A7="","",I7*H7) -> 462.97506 | L7: m² (painel = Anexo; base = envoltória) | M7: =IF($A7="","",IF(B7="CÓDIGO?","CÓDIGO NÃO ACHADO",IF($D7="","FALTA ITEM DO ANEXO",IF($D7="INDIRETO","",IF(COUNTIFS('Anexo III'!$B$8:$B$400,$D7,'Anexo III'!$E$8:$E$400,">0")=0,"ITEM NÃO ACHADO NO ANEXO","")))))
A8: MAT-01 | B8: =IF($A8="","",IF(ISNUMBER(MATCH($A8,'Cotação de Materiais'!$A$4:$A$200,0)),"MAT",IF(ISNUMBER(MATCH($A8,'Mão de Obra e Serviços'!$A$4:$A$200,0)),"MO","CÓDIGO?"))) -> MAT | C8: =IF($A8="","",IFERROR(INDEX('Cotação de Materiais'!$C$4:$C$200,MATCH($A8,'Cotação de Materiais'!$A$4:$A$200,0)),IFERROR(INDEX('Mão de Obra e Serviços'!$B$4:$B$200,MATCH($A8,'Mão de Obra e Serviços'!$A$4:$A$200,0)),""))) -> Chapas de MDF Comum 18mm | D8: A.2.3 | E8: 32 | F8: 1 | G8: =IF($A8="","",E8*IF(F8="",1,F8)) -> 32 | H8: =IF($A8="","",IF(SUMIF($A$6:$A$600,$A8,$G$6:$G$600)=0,0,G8/SUMIF($A$6:$A$600,$A8,$G$6:$G$600))) -> 0.080444456 | I8: =IF($A8="","",IFERROR(INDEX('Cotação de Materiais'!$H$4:$H$200,MATCH($A8,'Cotação de Materiais'!$A$4:$A$200,0)),IFERROR(INDEX('Mão de Obra e Serviços'!$G$4:$G$200,MATCH($A8,'Mão de Obra e Serviços'!$A$4:$A$200,0)),0))) -> 15607.36 | K8: =IF($A8="","",I8*H8) -> 1255.5256 | L8: m² (painel = Anexo; base = envoltória) | M8: =IF($A8="","",IF(B8="CÓDIGO?","CÓDIGO NÃO ACHADO",IF($D8="","FALTA ITEM DO ANEXO",IF($D8="INDIRETO","",IF(COUNTIFS('Anexo III'!$B$8:$B$400,$D8,'Anexo III'!$E$8:$E$400,">0")=0,"ITEM NÃO ACHADO NO ANEXO","")))))
A9: MAT-01 | B9: =IF($A9="","",IF(ISNUMBER(MATCH($A9,'Cotação de Materiais'!$A$4:$A$200,0)),"MAT",IF(ISNUMBER(MATCH($A9,'Mão de Obra e Serviços'!$A$4:$A$200,0)),"MO","CÓDIGO?"))) -> MAT | C9: =IF($A9="","",IFERROR(INDEX('Cotação de Materiais'!$C$4:$C$200,MATCH($A9,'Cotação de Materiais'!$A$4:$A$200,0)),IFERROR(INDEX('Mão de Obra e Serviços'!$B$4:$B$200,MATCH($A9,'Mão de Obra e Serviços'!$A$4:$A$200,0)),""))) -> Chapas de MDF Comum 18mm | D9: A.2.4 | E9: 25 | F9: 1 | G9: =IF($A9="","",E9*IF(F9="",1,F9)) -> 25 | H9: =IF($A9="","",IF(SUMIF($A$6:$A$600,$A9,$G$6:$G$600)=0,0,G9/SUMIF($A$6:$A$600,$A9,$G$6:$G$600))) -> 0.062847231 | I9: =IF($A9="","",IFERROR(INDEX('Cotação de Materiais'!$H$4:$H$200,MATCH($A9,'Cotação de Materiais'!$A$4:$A$200,0)),IFERROR(INDEX('Mão de Obra e Serviços'!$G$4:$G$200,MATCH($A9,'Mão de Obra e Serviços'!$A$4:$A$200,0)),0))) -> 15607.36 | K9: =IF($A9="","",I9*H9) -> 980.87936 | L9: m² (painel = Anexo; base = envoltória) | M9: =IF($A9="","",IF(B9="CÓDIGO?","CÓDIGO NÃO ACHADO",IF($D9="","FALTA ITEM DO ANEXO",IF($D9="INDIRETO","",IF(COUNTIFS('Anexo III'!$B$8:$B$400,$D9,'Anexo III'!$E$8:$E$400,">0")=0,"ITEM NÃO ACHADO NO ANEXO","")))))
A10: MAT-01 | B10: =IF($A10="","",IF(ISNUMBER(MATCH($A10,'Cotação de Materiais'!$A$4:$A$200,0)),"MAT",IF(ISNUMBER(MATCH($A10,'Mão de Obra e Serviços'!$A$4:$A$200,0)),"MO","CÓDIGO?"))) -> MAT | C10: =IF($A10="","",IFERROR(INDEX('Cotação de Materiais'!$C$4:$C$200,MATCH($A10,'Cotação de Materiais'!$A$4:$A$200,0)),IFERROR(INDEX('Mão de Obra e Serviços'!$B$4:$B$200,MATCH($A10,'Mão de Obra e Serviços'!$A$4:$A$200,0)),""))) -> Chapas de MDF Comum 18mm | D10: A.2.5 | E10: 16.5 | F10: 1 | G10: =IF($A10="","",E10*IF(F10="",1,F10)) -> 16.5 | H10: =IF($A10="","",IF(SUMIF($A$6:$A$600,$A10,$G$6:$G$600)=0,0,G10/SUMIF($A$6:$A$600,$A10,$G$6:$G$600))) -> 0.041479172 | I10: =IF($A10="","",IFERROR(INDEX('Cotação de Materiais'!$H$4:$H$200,MATCH($A10,'Cotação de Materiais'!$A$4:$A$200,0)),IFERROR(INDEX('Mão de Obra e Serviços'!$G$4:$G$200,MATCH($A10,'Mão de Obra e Serviços'!$A$4:$A$200,0)),0))) -> 15607.36 | K10: =IF($A10="","",I10*H10) -> 647.38038 | L10: m² (painel = Anexo; base = envoltória) | M10: =IF($A10="","",IF(B10="CÓDIGO?","CÓDIGO NÃO ACHADO",IF($D10="","FALTA ITEM DO ANEXO",IF($D10="INDIRETO","",IF(COUNTIFS('Anexo III'!$B$8:$B$400,$D10,'Anexo III'!$E$8:$E$400,">0")=0,"ITEM NÃO ACHADO NO ANEXO","")))))
A11: MAT-01 | B11: =IF($A11="","",IF(ISNUMBER(MATCH($A11,'Cotação de Materiais'!$A$4:$A$200,0)),"MAT",IF(ISNUMBER(MATCH($A11,'Mão de Obra e Serviços'!$A$4:$A$200,0)),"MO","CÓDIGO?"))) -> MAT | C11: =IF($A11="","",IFERROR(INDEX('Cotação de Materiais'!$C$4:$C$200,MATCH($A11,'Cotação de Materiais'!$A$4:$A$200,0)),IFERROR(INDEX('Mão de Obra e Serviços'!$B$4:$B$200,MATCH($A11,'Mão de Obra e Serviços'!$A$4:$A$200,0)),""))) -> Chapas de MDF Comum 18mm | D11: A.2.6 | E11: 3.8 | F11: 1 | G11: =IF($A11="","",E11*IF(F11="",1,F11)) -> 3.8 | H11: =IF($A11="","",IF(SUMIF($A$6:$A$600,$A11,$G$6:$G$600)=0,0,G11/SUMIF($A$6:$A$600,$A11,$G$6:$G$600))) -> 0.0095527791 | I11: =IF($A11="","",IFERROR(INDEX('Cotação de Materiais'!$H$4:$H$200,MATCH($A11,'Cotação de Materiais'!$A$4:$A$200,0)),IFERROR(INDEX('Mão de Obra e Serviços'!$G$4:$G$200,MATCH($A11,'Mão de Obra e Serviços'!$A$4:$A$200,0)),0))) -> 15607.36 | K11: =IF($A11="","",I11*H11) -> 149.09366 | L11: m² (painel = Anexo; base = envoltória) | M11: =IF($A11="","",IF(B11="CÓDIGO?","CÓDIGO NÃO ACHADO",IF($D11="","FALTA ITEM DO ANEXO",IF($D11="INDIRETO","",IF(COUNTIFS('Anexo III'!$B$8:$B$400,$D11,'Anexo III'!$E$8:$E$400,">0")=0,"ITEM NÃO ACHADO NO ANEXO","")))))
A12: MAT-01 | B12: =IF($A12="","",IF(ISNUMBER(MATCH($A12,'Cotação de Materiais'!$A$4:$A$200,0)),"MAT",IF(ISNUMBER(MATCH($A12,'Mão de Obra e Serviços'!$A$4:$A$200,0)),"MO","CÓDIGO?"))) -> MAT | C12: =IF($A12="","",IFERROR(INDEX('Cotação de Materiais'!$C$4:$C$200,MATCH($A12,'Cotação de Materiais'!$A$4:$A$200,0)),IFERROR(INDEX('Mão de Obra e Serviços'!$B$4:$B$200,MATCH($A12,'Mão de Obra e Serviços'!$A$4:$A$200,0)),""))) -> Chapas de MDF Comum 18mm | D12: A.2.7 | E12: 5.2 | F12: 1 | G12: =IF($A12="","",E12*IF(F12="",1,F12)) -> 5.2 | H12: =IF($A12="","",IF(SUMIF($A$6:$A$600,$A12,$G$6:$G$600)=0,0,G12/SUMIF($A$6:$A$600,$A12,$G$6:$G$600))) -> 0.013072224 | I12: =IF($A12="","",IFERROR(INDEX('Cotação de Materiais'!$H$4:$H$200,MATCH($A12,'Cotação de Materiais'!$A$4:$A$200,0)),IFERROR(INDEX('Mão de Obra e Serviços'!$G$4:$G$200,MATCH($A12,'Mão de Obra e Serviços'!$A$4:$A$200,0)),0))) -> 15607.36 | K12: =IF($A12="","",I12*H12) -> 204.02291 | L12: m² (painel = Anexo; base = envoltória) | M12: =IF($A12="","",IF(B12="CÓDIGO?","CÓDIGO NÃO ACHADO",IF($D12="","FALTA ITEM DO ANEXO",IF($D12="INDIRETO","",IF(COUNTIFS('Anexo III'!$B$8:$B$400,$D12,'Anexo III'!$E$8:$E$400,">0")=0,"ITEM NÃO ACHADO NO ANEXO","")))))
A13: MAT-01 | B13: =IF($A13="","",IF(ISNUMBER(MATCH($A13,'Cotação de Materiais'!$A$4:$A$200,0)),"MAT",IF(ISNUMBER(MATCH($A13,'Mão de Obra e Serviços'!$A$4:$A$200,0)),"MO","CÓDIGO?"))) -> MAT | C13: =IF($A13="","",IFERROR(INDEX('Cotação de Materiais'!$C$4:$C$200,MATCH($A13,'Cotação de Materiais'!$A$4:$A$200,0)),IFERROR(INDEX('Mão de Obra e Serviços'!$B$4:$B$200,MATCH($A13,'Mão de Obra e Serviços'!$A$4:$A$200,0)),""))) -> Chapas de MDF Comum 18mm | D13: A.2.8 | E13: 35 | F13: 1 | G13: =IF($A13="","",E13*IF(F13="",1,F13)) -> 35 | H13: =IF($A13="","",IF(SUMIF($A$6:$A$600,$A13,$G$6:$G$600)=0,0,G13/SUMIF($A$6:$A$600,$A13,$G$6:$G$600))) -> 0.087986123 | I13: =IF($A13="","",IFERROR(INDEX('Cotação de Materiais'!$H$4:$H$200,MATCH($A13,'Cotação de Materiais'!$A$4:$A$200,0)),IFERROR(INDEX('Mão de Obra e Serviços'!$G$4:$G$200,MATCH($A13,'Mão de Obra e Serviços'!$A$4:$A$200,0)),0))) -> 15607.36 | K13: =IF($A13="","",I13*H13) -> 1373.2311 | L13: m² (painel = Anexo; base = envoltória) | M13: =IF($A13="","",IF(B13="CÓDIGO?","CÓDIGO NÃO ACHADO",IF($D13="","FALTA ITEM DO ANEXO",IF($D13="INDIRETO","",IF(COUNTIFS('Anexo III'!$B$8:$B$400,$D13,'Anexo III'!$E$8:$E$400,">0")=0,"ITEM NÃO ACHADO NO ANEXO","")))))
A14: MAT-01 | B14: =IF($A14="","",IF(ISNUMBER(MATCH($A14,'Cotação de Materiais'!$A$4:$A$200,0)),"MAT",IF(ISNUMBER(MATCH($A14,'Mão de Obra e Serviços'!$A$4:$A$200,0)),"MO","CÓDIGO?"))) -> MAT | C14: =IF($A14="","",IFERROR(INDEX('Cotação de Materiais'!$C$4:$C$200,MATCH($A14,'Cotação de Materiais'!$A$4:$A$200,0)),IFERROR(INDEX('Mão de Obra e Serviços'!$B$4:$B$200,MATCH($A14,'Mão de Obra e Serviços'!$A$4:$A$200,0)),""))) -> Chapas de MDF Comum 18mm | D14: A.2.9 | E14: 97 | F14: 1 | G14: =IF($A14="","",E14*IF(F14="",1,F14)) -> 97 | H14: =IF($A14="","",IF(SUMIF($A$6:$A$600,$A14,$G$6:$G$600)=0,0,G14/SUMIF($A$6:$A$600,$A14,$G$6:$G$600))) -> 0.24384726 | I14: =IF($A14="","",IFERROR(INDEX('Cotação de Materiais'!$H$4:$H$200,MATCH($A14,'Cotação de Materiais'!$A$4:$A$200,0)),IFERROR(INDEX('Mão de Obra e Serviços'!$G$4:$G$200,MATCH($A14,'Mão de Obra e Serviços'!$A$4:$A$200,0)),0))) -> 15607.36 | K14: =IF($A14="","",I14*H14) -> 3805.8119 | L14: m² (painel = Anexo; base = envoltória) | M14: =IF($A14="","",IF(B14="CÓDIGO?","CÓDIGO NÃO ACHADO",IF($D14="","FALTA ITEM DO ANEXO",IF($D14="INDIRETO","",IF(COUNTIFS('Anexo III'!$B$8:$B$400,$D14,'Anexo III'!$E$8:$E$400,">0")=0,"ITEM NÃO ACHADO NO ANEXO","")))))
A15: MAT-01 | B15: =IF($A15="","",IF(ISNUMBER(MATCH($A15,'Cotação de Materiais'!$A$4:$A$200,0)),"MAT",IF(ISNUMBER(MATCH($A15,'Mão de Obra e Serviços'!$A$4:$A$200,0)),"MO","CÓDIGO?"))) -> MAT | C15: =IF($A15="","",IFERROR(INDEX('Cotação de Materiais'!$C$4:$C$200,MATCH($A15,'Cotação de Materiais'!$A$4:$A$200,0)),IFERROR(INDEX('Mão de Obra e Serviços'!$B$4:$B$200,MATCH($A15,'Mão de Obra e Serviços'!$A$4:$A$200,0)),""))) -> Chapas de MDF Comum 18mm | D15: A.4.4 | E15: 38.58 | F15: 1 | G15: =IF($A15="","",E15*IF(F15="",1,F15)) -> 38.58 | H15: =IF($A15="","",IF(SUMIF($A$6:$A$600,$A15,$G$6:$G$600)=0,0,G15/SUMIF($A$6:$A$600,$A15,$G$6:$G$600))) -> 0.096985847 | I15: =IF($A15="","",IFERROR(INDEX('Cotação de Materiais'!$H$4:$H$200,MATCH($A15,'Cotação de Materiais'!$A$4:$A$200,0)),IFERROR(INDEX('Mão de Obra e Serviços'!$G$4:$G$200,MATCH($A15,'Mão de Obra e Serviços'!$A$4:$A$200,0)),0))) -> 15607.36 | K15: =IF($A15="","",I15*H15) -> 1513.693 | L15: m² (painel = Anexo; base = envoltória) | M15: =IF($A15="","",IF(B15="CÓDIGO?","CÓDIGO NÃO ACHADO",IF($D15="","FALTA ITEM DO ANEXO",IF($D15="INDIRETO","",IF(COUNTIFS('Anexo III'!$B$8:$B$400,$D15,'Anexo III'!$E$8:$E$400,">0")=0,"ITEM NÃO ACHADO NO ANEXO","")))))
A16: MAT-01 | B16: =IF($A16="","",IF(ISNUMBER(MATCH($A16,'Cotação de Materiais'!$A$4:$A$200,0)),"MAT",IF(ISNUMBER(MATCH($A16,'Mão de Obra e Serviços'!$A$4:$A$200,0)),"MO","CÓDIGO?"))) -> MAT | C16: =IF($A16="","",IFERROR(INDEX('Cotação de Materiais'!$C$4:$C$200,MATCH($A16,'Cotação de Materiais'!$A$4:$A$200,0)),IFERROR(INDEX('Mão de Obra e Serviços'!$B$4:$B$200,MATCH($A16,'Mão de Obra e Serviços'!$A$4:$A$200,0)),""))) -> Chapas de MDF Comum 18mm | D16: A.4.5 | E16: 12.5 | F16: 1 | G16: =IF($A16="","",E16*IF(F16="",1,F16)) -> 12.5 | H16: =IF($A16="","",IF(SUMIF($A$6:$A$600,$A16,$G$6:$G$600)=0,0,G16/SUMIF($A$6:$A$600,$A16,$G$6:$G$600))) -> 0.031423615 | I16: =IF($A16="","",IFERROR(INDEX('Cotação de Materiais'!$H$4:$H$200,MATCH($A16,'Cotação de Materiais'!$A$4:$A$200,0)),IFERROR(INDEX('Mão de Obra e Serviços'!$G$4:$G$200,MATCH($A16,'Mão de Obra e Serviços'!$A$4:$A$200,0)),0))) -> 15607.36 | K16: =IF($A16="","",I16*H16) -> 490.43968 | L16: m² (painel = Anexo; base = envoltória) | M16: =IF($A16="","",IF(B16="CÓDIGO?","CÓDIGO NÃO ACHADO",IF($D16="","FALTA ITEM DO ANEXO",IF($D16="INDIRETO","",IF(COUNTIFS('Anexo III'!$B$8:$B$400,$D16,'Anexo III'!$E$8:$E$400,">0")=0,"ITEM NÃO ACHADO NO ANEXO","")))))
A17: MAT-01 | B17: =IF($A17="","",IF(ISNUMBER(MATCH($A17,'Cotação de Materiais'!$A$4:$A$200,0)),"MAT",IF(ISNUMBER(MATCH($A17,'Mão de Obra e Serviços'!$A$4:$A$200,0)),"MO","CÓDIGO?"))) -> MAT | C17: =IF($A17="","",IFERROR(INDEX('Cotação de Materiais'!$C$4:$C$200,MATCH($A17,'Cotação de Materiais'!$A$4:$A$200,0)),IFERROR(INDEX('Mão de Obra e Serviços'!$B$4:$B$200,MATCH($A17,'Mão de Obra e Serviços'!$A$4:$A$200,0)),""))) -> Chapas de MDF Comum 18mm | D17: A.4.6 | E17: 2.11 | F17: 1 | G17: =IF($A17="","",E17*IF(F17="",1,F17)) -> 2.11 | H17: =IF($A17="","",IF(SUMIF($A$6:$A$600,$A17,$G$6:$G$600)=0,0,G17/SUMIF($A$6:$A$600,$A17,$G$6:$G$600))) -> 0.0053043063 | I17: =IF($A17="","",IFERROR(INDEX('Cotação de Materiais'!$H$4:$H$200,MATCH($A17,'Cotação de Materiais'!$A$4:$A$200,0)),IFERROR(INDEX('Mão de Obra e Serviços'!$G$4:$G$200,MATCH($A17,'Mão de Obra e Serviços'!$A$4:$A$200,0)),0))) -> 15607.36 | K17: =IF($A17="","",I17*H17) -> 82.786218 | L17: m² (painel = Anexo; base = envoltória) | M17: =IF($A17="","",IF(B17="CÓDIGO?","CÓDIGO NÃO ACHADO",IF($D17="","FALTA ITEM DO ANEXO",IF($D17="INDIRETO","",IF(COUNTIFS('Anexo III'!$B$8:$B$400,$D17,'Anexo III'!$E$8:$E$400,">0")=0,"ITEM NÃO ACHADO NO ANEXO","")))))
... A267: ENG-01 | B267: =IF($A267="","",IF(ISNUMBER(MATCH($A267,'Cotação de Materiais'!$A$4:$A$200,0)),"MAT",IF(ISNUMBER(MATCH($A267,'Mão de Obra e Serviços'!$A$4:$A$200,0)),"MO","CÓDIGO?"))) -> MO | C267: =IF($A267="","",IFERROR(INDEX('Cotação de Materiais'!$C$4:$C$200,MATCH($A267,'Cotação de Materiais'!$A$4:$A$200,0)),IFERROR(INDEX('Mão de Obra e Serviços'!$B$4:$B$200,MATCH($A267,'Mão de Obra e Serviços'!$A$4:$A$200,0)),""))) -> ART — referência interna | D267: INDIRETO | E267: 1 | F267: 1 | G267: =IF($A267="","",E267*IF(F267="",1,F267)) -> 1 | H267: =IF($A267="","",IF(SUMIF($A$6:$A$600,$A267,$G$6:$G$600)=0,0,G267/SUMIF($A$6:$A$600,$A267,$G$6:$G$600))) -> 1 | I267: =IF($A267="","",IFERROR(INDEX('Cotação de Materiais'!$H$4:$H$200,MATCH($A267,'Cotação de Materiais'!$A$4:$A$200,0)),IFERROR(INDEX('Mão de Obra e Serviços'!$G$4:$G$200,MATCH($A267,'Mão de Obra e Serviços'!$A$4:$A$200,0)),0))) -> 1500 | K267: =IF($A267="","",I267*H267) -> 1500 | L267: logística/ART → indireto | M267: =IF($A267="","",IF(B267="CÓDIGO?","CÓDIGO NÃO ACHADO",IF($D267="","FALTA ITEM DO ANEXO",IF($D267="INDIRETO","",IF(COUNTIFS('Anexo III'!$B$8:$B$400,$D267,'Anexo III'!$E$8:$E$400,">0")=0,"ITEM NÃO ACHADO NO ANEXO","")))))
B268: =IF($A268="","",IF(ISNUMBER(MATCH($A268,'Cotação de Materiais'!$A$4:$A$200,0)),"MAT",IF(ISNUMBER(MATCH($A268,'Mão de Obra e Serviços'!$A$4:$A$200,0)),"MO","CÓDIGO?"))) | C268: =IF($A268="","",IFERROR(INDEX('Cotação de Materiais'!$C$4:$C$200,MATCH($A268,'Cotação de Materiais'!$A$4:$A$200,0)),IFERROR(INDEX('Mão de Obra e Serviços'!$B$4:$B$200,MATCH($A268,'Mão de Obra e Serviços'!$A$4:$A$200,0)),""))) | G268: =IF($A268="","",E268*IF(F268="",1,F268)) | H268: =IF($A268="","",IF(SUMIF($A$6:$A$600,$A268,$G$6:$G$600)=0,0,G268/SUMIF($A$6:$A$600,$A268,$G$6:$G$600))) | I268: =IF($A268="","",IFERROR(INDEX('Cotação de Materiais'!$H$4:$H$200,MATCH($A268,'Cotação de Materiais'!$A$4:$A$200,0)),IFERROR(INDEX('Mão de Obra e Serviços'!$G$4:$G$200,MATCH($A268,'Mão de Obra e Serviços'!$A$4:$A$200,0)),0))) | K268: =IF($A268="","",I268*H268) | M268: =IF($A268="","",IF(B268="CÓDIGO?","CÓDIGO NÃO ACHADO",IF($D268="","FALTA ITEM DO ANEXO",IF($D268="INDIRETO","",IF(COUNTIFS('Anexo III'!$B$8:$B$400,$D268,'Anexo III'!$E$8:$E$400,">0")=0,"ITEM NÃO ACHADO NO ANEXO","")))))
B269: =IF($A269="","",IF(ISNUMBER(MATCH($A269,'Cotação de Materiais'!$A$4:$A$200,0)),"MAT",IF(ISNUMBER(MATCH($A269,'Mão de Obra e Serviços'!$A$4:$A$200,0)),"MO","CÓDIGO?"))) | C269: =IF($A269="","",IFERROR(INDEX('Cotação de Materiais'!$C$4:$C$200,MATCH($A269,'Cotação de Materiais'!$A$4:$A$200,0)),IFERROR(INDEX('Mão de Obra e Serviços'!$B$4:$B$200,MATCH($A269,'Mão de Obra e Serviços'!$A$4:$A$200,0)),""))) | G269: =IF($A269="","",E269*IF(F269="",1,F269)) | H269: =IF($A269="","",IF(SUMIF($A$6:$A$600,$A269,$G$6:$G$600)=0,0,G269/SUMIF($A$6:$A$600,$A269,$G$6:$G$600))) | I269: =IF($A269="","",IFERROR(INDEX('Cotação de Materiais'!$H$4:$H$200,MATCH($A269,'Cotação de Materiais'!$A$4:$A$200,0)),IFERROR(INDEX('Mão de Obra e Serviços'!$G$4:$G$200,MATCH($A269,'Mão de Obra e Serviços'!$A$4:$A$200,0)),0))) | K269: =IF($A269="","",I269*H269) | M269: =IF($A269="","",IF(B269="CÓDIGO?","CÓDIGO NÃO ACHADO",IF($D269="","FALTA ITEM DO ANEXO",IF($D269="INDIRETO","",IF(COUNTIFS('Anexo III'!$B$8:$B$400,$D269,'Anexo III'!$E$8:$E$400,">0")=0,"ITEM NÃO ACHADO NO ANEXO","")))))
B270: =IF($A270="","",IF(ISNUMBER(MATCH($A270,'Cotação de Materiais'!$A$4:$A$200,0)),"MAT",IF(ISNUMBER(MATCH($A270,'Mão de Obra e Serviços'!$A$4:$A$200,0)),"MO","CÓDIGO?"))) | C270: =IF($A270="","",IFERROR(INDEX('Cotação de Materiais'!$C$4:$C$200,MATCH($A270,'Cotação de Materiais'!$A$4:$A$200,0)),IFERROR(INDEX('Mão de Obra e Serviços'!$B$4:$B$200,MATCH($A270,'Mão de Obra e Serviços'!$A$4:$A$200,0)),""))) | G270: =IF($A270="","",E270*IF(F270="",1,F270)) | H270: =IF($A270="","",IF(SUMIF($A$6:$A$600,$A270,$G$6:$G$600)=0,0,G270/SUMIF($A$6:$A$600,$A270,$G$6:$G$600))) | I270: =IF($A270="","",IFERROR(INDEX('Cotação de Materiais'!$H$4:$H$200,MATCH($A270,'Cotação de Materiais'!$A$4:$A$200,0)),IFERROR(INDEX('Mão de Obra e Serviços'!$G$4:$G$200,MATCH($A270,'Mão de Obra e Serviços'!$A$4:$A$200,0)),0))) | K270: =IF($A270="","",I270*H270) | M270: =IF($A270="","",IF(B270="CÓDIGO?","CÓDIGO NÃO ACHADO",IF($D270="","FALTA ITEM DO ANEXO",IF($D270="INDIRETO","",IF(COUNTIFS('Anexo III'!$B$8:$B$400,$D270,'Anexo III'!$E$8:$E$400,">0")=0,"ITEM NÃO ACHADO NO ANEXO","")))))
B271: =IF($A271="","",IF(ISNUMBER(MATCH($A271,'Cotação de Materiais'!$A$4:$A$200,0)),"MAT",IF(ISNUMBER(MATCH($A271,'Mão de Obra e Serviços'!$A$4:$A$200,0)),"MO","CÓDIGO?"))) | C271: =IF($A271="","",IFERROR(INDEX('Cotação de Materiais'!$C$4:$C$200,MATCH($A271,'Cotação de Materiais'!$A$4:$A$200,0)),IFERROR(INDEX('Mão de Obra e Serviços'!$B$4:$B$200,MATCH($A271,'Mão de Obra e Serviços'!$A$4:$A$200,0)),""))) | G271: =IF($A271="","",E271*IF(F271="",1,F271)) | H271: =IF($A271="","",IF(SUMIF($A$6:$A$600,$A271,$G$6:$G$600)=0,0,G271/SUMIF($A$6:$A$600,$A271,$G$6:$G$600))) | I271: =IF($A271="","",IFERROR(INDEX('Cotação de Materiais'!$H$4:$H$200,MATCH($A271,'Cotação de Materiais'!$A$4:$A$200,0)),IFERROR(INDEX('Mão de Obra e Serviços'!$G$4:$G$200,MATCH($A271,'Mão de Obra e Serviços'!$A$4:$A$200,0)),0))) | K271: =IF($A271="","",I271*H271) | M271: =IF($A271="","",IF(B271="CÓDIGO?","CÓDIGO NÃO ACHADO",IF($D271="","FALTA ITEM DO ANEXO",IF($D271="INDIRETO","",IF(COUNTIFS('Anexo III'!$B$8:$B$400,$D271,'Anexo III'!$E$8:$E$400,">0")=0,"ITEM NÃO ACHADO NO ANEXO","")))))
B272: =IF($A272="","",IF(ISNUMBER(MATCH($A272,'Cotação de Materiais'!$A$4:$A$200,0)),"MAT",IF(ISNUMBER(MATCH($A272,'Mão de Obra e Serviços'!$A$4:$A$200,0)),"MO","CÓDIGO?"))) | C272: =IF($A272="","",IFERROR(INDEX('Cotação de Materiais'!$C$4:$C$200,MATCH($A272,'Cotação de Materiais'!$A$4:$A$200,0)),IFERROR(INDEX('Mão de Obra e Serviços'!$B$4:$B$200,MATCH($A272,'Mão de Obra e Serviços'!$A$4:$A$200,0)),""))) | G272: =IF($A272="","",E272*IF(F272="",1,F272)) | H272: =IF($A272="","",IF(SUMIF($A$6:$A$600,$A272,$G$6:$G$600)=0,0,G272/SUMIF($A$6:$A$600,$A272,$G$6:$G$600))) | I272: =IF($A272="","",IFERROR(INDEX('Cotação de Materiais'!$H$4:$H$200,MATCH($A272,'Cotação de Materiais'!$A$4:$A$200,0)),IFERROR(INDEX('Mão de Obra e Serviços'!$G$4:$G$200,MATCH($A272,'Mão de Obra e Serviços'!$A$4:$A$200,0)),0))) | K272: =IF($A272="","",I272*H272) | M272: =IF($A272="","",IF(B272="CÓDIGO?","CÓDIGO NÃO ACHADO",IF($D272="","FALTA ITEM DO ANEXO",IF($D272="INDIRETO","",IF(COUNTIFS('Anexo III'!$B$8:$B$400,$D272,'Anexo III'!$E$8:$E$400,">0")=0,"ITEM NÃO ACHADO NO ANEXO","")))))
B273: =IF($A273="","",IF(ISNUMBER(MATCH($A273,'Cotação de Materiais'!$A$4:$A$200,0)),"MAT",IF(ISNUMBER(MATCH($A273,'Mão de Obra e Serviços'!$A$4:$A$200,0)),"MO","CÓDIGO?"))) | C273: =IF($A273="","",IFERROR(INDEX('Cotação de Materiais'!$C$4:$C$200,MATCH($A273,'Cotação de Materiais'!$A$4:$A$200,0)),IFERROR(INDEX('Mão de Obra e Serviços'!$B$4:$B$200,MATCH($A273,'Mão de Obra e Serviços'!$A$4:$A$200,0)),""))) | G273: =IF($A273="","",E273*IF(F273="",1,F273)) | H273: =IF($A273="","",IF(SUMIF($A$6:$A$600,$A273,$G$6:$G$600)=0,0,G273/SUMIF($A$6:$A$600,$A273,$G$6:$G$600))) | I273: =IF($A273="","",IFERROR(INDEX('Cotação de Materiais'!$H$4:$H$200,MATCH($A273,'Cotação de Materiais'!$A$4:$A$200,0)),IFERROR(INDEX('Mão de Obra e Serviços'!$G$4:$G$200,MATCH($A273,'Mão de Obra e Serviços'!$A$4:$A$200,0)),0))) | K273: =IF($A273="","",I273*H273) | M273: =IF($A273="","",IF(B273="CÓDIGO?","CÓDIGO NÃO ACHADO",IF($D273="","FALTA ITEM DO ANEXO",IF($D273="INDIRETO","",IF(COUNTIFS('Anexo III'!$B$8:$B$400,$D273,'Anexo III'!$E$8:$E$400,">0")=0,"ITEM NÃO ACHADO NO ANEXO","")))))
B274: =IF($A274="","",IF(ISNUMBER(MATCH($A274,'Cotação de Materiais'!$A$4:$A$200,0)),"MAT",IF(ISNUMBER(MATCH($A274,'Mão de Obra e Serviços'!$A$4:$A$200,0)),"MO","CÓDIGO?"))) | C274: =IF($A274="","",IFERROR(INDEX('Cotação de Materiais'!$C$4:$C$200,MATCH($A274,'Cotação de Materiais'!$A$4:$A$200,0)),IFERROR(INDEX('Mão de Obra e Serviços'!$B$4:$B$200,MATCH($A274,'Mão de Obra e Serviços'!$A$4:$A$200,0)),""))) | G274: =IF($A274="","",E274*IF(F274="",1,F274)) | H274: =IF($A274="","",IF(SUMIF($A$6:$A$600,$A274,$G$6:$G$600)=0,0,G274/SUMIF($A$6:$A$600,$A274,$G$6:$G$600))) | I274: =IF($A274="","",IFERROR(INDEX('Cotação de Materiais'!$H$4:$H$200,MATCH($A274,'Cotação de Materiais'!$A$4:$A$200,0)),IFERROR(INDEX('Mão de Obra e Serviços'!$G$4:$G$200,MATCH($A274,'Mão de Obra e Serviços'!$A$4:$A$200,0)),0))) | K274: =IF($A274="","",I274*H274) | M274: =IF($A274="","",IF(B274="CÓDIGO?","CÓDIGO NÃO ACHADO",IF($D274="","FALTA ITEM DO ANEXO",IF($D274="INDIRETO","",IF(COUNTIFS('Anexo III'!$B$8:$B$400,$D274,'Anexo III'!$E$8:$E$400,">0")=0,"ITEM NÃO ACHADO NO ANEXO","")))))
B275: =IF($A275="","",IF(ISNUMBER(MATCH($A275,'Cotação de Materiais'!$A$4:$A$200,0)),"MAT",IF(ISNUMBER(MATCH($A275,'Mão de Obra e Serviços'!$A$4:$A$200,0)),"MO","CÓDIGO?"))) | C275: =IF($A275="","",IFERROR(INDEX('Cotação de Materiais'!$C$4:$C$200,MATCH($A275,'Cotação de Materiais'!$A$4:$A$200,0)),IFERROR(INDEX('Mão de Obra e Serviços'!$B$4:$B$200,MATCH($A275,'Mão de Obra e Serviços'!$A$4:$A$200,0)),""))) | G275: =IF($A275="","",E275*IF(F275="",1,F275)) | H275: =IF($A275="","",IF(SUMIF($A$6:$A$600,$A275,$G$6:$G$600)=0,0,G275/SUMIF($A$6:$A$600,$A275,$G$6:$G$600))) | I275: =IF($A275="","",IFERROR(INDEX('Cotação de Materiais'!$H$4:$H$200,MATCH($A275,'Cotação de Materiais'!$A$4:$A$200,0)),IFERROR(INDEX('Mão de Obra e Serviços'!$G$4:$G$200,MATCH($A275,'Mão de Obra e Serviços'!$A$4:$A$200,0)),0))) | K275: =IF($A275="","",I275*H275) | M275: =IF($A275="","",IF(B275="CÓDIGO?","CÓDIGO NÃO ACHADO",IF($D275="","FALTA ITEM DO ANEXO",IF($D275="INDIRETO","",IF(COUNTIFS('Anexo III'!$B$8:$B$400,$D275,'Anexo III'!$E$8:$E$400,">0")=0,"ITEM NÃO ACHADO NO ANEXO","")))))
B276: =IF($A276="","",IF(ISNUMBER(MATCH($A276,'Cotação de Materiais'!$A$4:$A$200,0)),"MAT",IF(ISNUMBER(MATCH($A276,'Mão de Obra e Serviços'!$A$4:$A$200,0)),"MO","CÓDIGO?"))) | C276: =IF($A276="","",IFERROR(INDEX('Cotação de Materiais'!$C$4:$C$200,MATCH($A276,'Cotação de Materiais'!$A$4:$A$200,0)),IFERROR(INDEX('Mão de Obra e Serviços'!$B$4:$B$200,MATCH($A276,'Mão de Obra e Serviços'!$A$4:$A$200,0)),""))) | G276: =IF($A276="","",E276*IF(F276="",1,F276)) | H276: =IF($A276="","",IF(SUMIF($A$6:$A$600,$A276,$G$6:$G$600)=0,0,G276/SUMIF($A$6:$A$600,$A276,$G$6:$G$600))) | I276: =IF($A276="","",IFERROR(INDEX('Cotação de Materiais'!$H$4:$H$200,MATCH($A276,'Cotação de Materiais'!$A$4:$A$200,0)),IFERROR(INDEX('Mão de Obra e Serviços'!$G$4:$G$200,MATCH($A276,'Mão de Obra e Serviços'!$A$4:$A$200,0)),0))) | K276: =IF($A276="","",I276*H276) | M276: =IF($A276="","",IF(B276="CÓDIGO?","CÓDIGO NÃO ACHADO",IF($D276="","FALTA ITEM DO ANEXO",IF($D276="INDIRETO","",IF(COUNTIFS('Anexo III'!$B$8:$B$400,$D276,'Anexo III'!$E$8:$E$400,">0")=0,"ITEM NÃO ACHADO NO ANEXO","")))))
B277: =IF($A277="","",IF(ISNUMBER(MATCH($A277,'Cotação de Materiais'!$A$4:$A$200,0)),"MAT",IF(ISNUMBER(MATCH($A277,'Mão de Obra e Serviços'!$A$4:$A$200,0)),"MO","CÓDIGO?"))) | C277: =IF($A277="","",IFERROR(INDEX('Cotação de Materiais'!$C$4:$C$200,MATCH($A277,'Cotação de Materiais'!$A$4:$A$200,0)),IFERROR(INDEX('Mão de Obra e Serviços'!$B$4:$B$200,MATCH($A277,'Mão de Obra e Serviços'!$A$4:$A$200,0)),""))) | G277: =IF($A277="","",E277*IF(F277="",1,F277)) | H277: =IF($A277="","",IF(SUMIF($A$6:$A$600,$A277,$G$6:$G$600)=0,0,G277/SUMIF($A$6:$A$600,$A277,$G$6:$G$600))) | I277: =IF($A277="","",IFERROR(INDEX('Cotação de Materiais'!$H$4:$H$200,MATCH($A277,'Cotação de Materiais'!$A$4:$A$200,0)),IFERROR(INDEX('Mão de Obra e Serviços'!$G$4:$G$200,MATCH($A277,'Mão de Obra e Serviços'!$A$4:$A$200,0)),0))) | K277: =IF($A277="","",I277*H277) | M277: =IF($A277="","",IF(B277="CÓDIGO?","CÓDIGO NÃO ACHADO",IF($D277="","FALTA ITEM DO ANEXO",IF($D277="INDIRETO","",IF(COUNTIFS('Anexo III'!$B$8:$B$400,$D277,'Anexo III'!$E$8:$E$400,">0")=0,"ITEM NÃO ACHADO NO ANEXO","")))))
B278: =IF($A278="","",IF(ISNUMBER(MATCH($A278,'Cotação de Materiais'!$A$4:$A$200,0)),"MAT",IF(ISNUMBER(MATCH($A278,'Mão de Obra e Serviços'!$A$4:$A$200,0)),"MO","CÓDIGO?"))) | C278: =IF($A278="","",IFERROR(INDEX('Cotação de Materiais'!$C$4:$C$200,MATCH($A278,'Cotação de Materiais'!$A$4:$A$200,0)),IFERROR(INDEX('Mão de Obra e Serviços'!$B$4:$B$200,MATCH($A278,'Mão de Obra e Serviços'!$A$4:$A$200,0)),""))) | G278: =IF($A278="","",E278*IF(F278="",1,F278)) | H278: =IF($A278="","",IF(SUMIF($A$6:$A$600,$A278,$G$6:$G$600)=0,0,G278/SUMIF($A$6:$A$600,$A278,$G$6:$G$600))) | I278: =IF($A278="","",IFERROR(INDEX('Cotação de Materiais'!$H$4:$H$200,MATCH($A278,'Cotação de Materiais'!$A$4:$A$200,0)),IFERROR(INDEX('Mão de Obra e Serviços'!$G$4:$G$200,MATCH($A278,'Mão de Obra e Serviços'!$A$4:$A$200,0)),0))) | K278: =IF($A278="","",I278*H278) | M278: =IF($A278="","",IF(B278="CÓDIGO?","CÓDIGO NÃO ACHADO",IF($D278="","FALTA ITEM DO ANEXO",IF($D278="INDIRETO","",IF(COUNTIFS('Anexo III'!$B$8:$B$400,$D278,'Anexo III'!$E$8:$E$400,">0")=0,"ITEM NÃO ACHADO NO ANEXO","")))))
B279: =IF($A279="","",IF(ISNUMBER(MATCH($A279,'Cotação de Materiais'!$A$4:$A$200,0)),"MAT",IF(ISNUMBER(MATCH($A279,'Mão de Obra e Serviços'!$A$4:$A$200,0)),"MO","CÓDIGO?"))) | C279: =IF($A279="","",IFERROR(INDEX('Cotação de Materiais'!$C$4:$C$200,MATCH($A279,'Cotação de Materiais'!$A$4:$A$200,0)),IFERROR(INDEX('Mão de Obra e Serviços'!$B$4:$B$200,MATCH($A279,'Mão de Obra e Serviços'!$A$4:$A$200,0)),""))) | G279: =IF($A279="","",E279*IF(F279="",1,F279)) | H279: =IF($A279="","",IF(SUMIF($A$6:$A$600,$A279,$G$6:$G$600)=0,0,G279/SUMIF($A$6:$A$600,$A279,$G$6:$G$600))) | I279: =IF($A279="","",IFERROR(INDEX('Cotação de Materiais'!$H$4:$H$200,MATCH($A279,'Cotação de Materiais'!$A$4:$A$200,0)),IFERROR(INDEX('Mão de Obra e Serviços'!$G$4:$G$200,MATCH($A279,'Mão de Obra e Serviços'!$A$4:$A$200,0)),0))) | K279: =IF($A279="","",I279*H279) | M279: =IF($A279="","",IF(B279="CÓDIGO?","CÓDIGO NÃO ACHADO",IF($D279="","FALTA ITEM DO ANEXO",IF($D279="INDIRETO","",IF(COUNTIFS('Anexo III'!$B$8:$B$400,$D279,'Anexo III'!$E$8:$E$400,">0")=0,"ITEM NÃO ACHADO NO ANEXO","")))))
... B600: =IF($A600="","",IF(ISNUMBER(MATCH($A600,'Cotação de Materiais'!$A$4:$A$200,0)),"MAT",IF(ISNUMBER(MATCH($A600,'Mão de Obra e Serviços'!$A$4:$A$200,0)),"MO","CÓDIGO?"))) | C600: =IF($A600="","",IFERROR(INDEX('Cotação de Materiais'!$C$4:$C$200,MATCH($A600,'Cotação de Materiais'!$A$4:$A$200,0)),IFERROR(INDEX('Mão de Obra e Serviços'!$B$4:$B$200,MATCH($A600,'Mão de Obra e Serviços'!$A$4:$A$200,0)),""))) | G600: =IF($A600="","",E600*IF(F600="",1,F600)) | H600: =IF($A600="","",IF(SUMIF($A$6:$A$600,$A600,$G$6:$G$600)=0,0,G600/SUMIF($A$6:$A$600,$A600,$G$6:$G$600))) | I600: =IF($A600="","",IFERROR(INDEX('Cotação de Materiais'!$H$4:$H$200,MATCH($A600,'Cotação de Materiais'!$A$4:$A$200,0)),IFERROR(INDEX('Mão de Obra e Serviços'!$G$4:$G$200,MATCH($A600,'Mão de Obra e Serviços'!$A$4:$A$200,0)),0))) | K600: =IF($A600="","",I600*H600) | M600: =IF($A600="","",IF(B600="CÓDIGO?","CÓDIGO NÃO ACHADO",IF($D600="","FALTA ITEM DO ANEXO",IF($D600="INDIRETO","",IF(COUNTIFS('Anexo III'!$B$8:$B$400,$D600,'Anexo III'!$E$8:$E$400,">0")=0,"ITEM NÃO ACHADO NO ANEXO","")))))

Sheet Anexo III
A1: ANEXO III — PREÇOS GERADOS PARA A PLANILHA DO SESC
A2: CÓPIA INTERLIGADA DA PLANILHA DO SESC: mesma linha e mesmas colunas F (material) e G (MO) da oficial. Para preencher a oficial: copie o bloco indicado na coluna M e cole na MESMA faixa da oficial com COLAR ESPECIAL > VALORES (Ctrl+Alt+V > Valores). Nunca colar normal: leva fórmula e cria vínculo externo.
C3: TOTAL DO ANEXO → | E3: Centavos: | F3: =ROUND(Precificação!B8-SUMPRODUCT(E8:E400,V8:V400)-SUMPRODUCT(E8:E400,W8:W400),2) -> -0.42 | I3: =SUM(I8:I400) -> 149738.47 | J3: =SUM(J8:J400) -> 189761.53 | K3: =SUM(K8:K400) -> 339500 | L3: =IF(AND(ABS(K3-Precificação!B8)<0.005,Precificação!B30=0),"FECHA NO PREÇO","NÃO FECHA / CONFERIR RATEIO") -> FECHA NO PREÇO | N3: =SUM(N8:N400) -> 78254.481 | O3: =SUM(O8:O400) -> 98194.333 | P3: =SUM(P8:P400) -> 280 | Q3: =SUM(Q8:Q400) -> 20367.667 | R3: =SUM(R8:R400) -> 197096.48 | S3: =SUM(S8:S400) -> 149736.24 | T3: =SUM(T8:T400) -> 189763.76
A4: Nova licitação: cole Item / Item memorial / Descrição / Un / Qtd nas colunas A–E nas MESMAS linhas em que estão na planilha oficial. | P4: Indireto material a ratear: | R4: ='Rateio Anexo'!G3 -> 280 | S4: Indireto MO a ratear: | T4: ='Rateio Anexo'!K3 -> 20367.667
N5: CÁLCULO (não copiar) →
A7: ITEM | B7: ITEM MEMORIAL | C7: DESCRIÇÃO | D7: UN. | E7: QDE. | F7: UNIT. MATERIAL | G7: UNIT. MÃO-DE-OBRA | H7: UNIT. TOTAL | I7: TOTAL MATERIAL | J7: TOTAL MÃO-DE-OBRA | K7: TOTAL | L7: STATUS | M7: COLAR NA OFICIAL (valores) | N7: Custo mat. direto | O7: Custo MO direto | P7: Custo mat. indireto | Q7: Custo MO indireto | R7: Custo total | S7: Venda material | T7: Venda MO | U7: Grade (R$) | V7: Unit. mat. arred. | W7: Unit. MO arred. | X7: fim bloco
B8: A | C8: PROJETO EXPOGRAFICO | F8: =IF($E8="","",V8) | G8: =IF($E8="","",ROUND(W8+IF($B8=Precificação!$B$26,$F$3/$E8,0),2)) | H8: =IF($E8="","",F8+G8) | I8: =IF($E8="","",$E8*F8) | J8: =IF($E8="","",$E8*G8) | K8: =IF($E8="","",I8+J8) | L8: =IF($E8="","",IF(R8=0,"SEM CUSTO — falta linha de custo","OK")) | M8: =IF(AND(ISNUMBER(E8),NOT(ISNUMBER(E7))),"F"&ROW()&":G"&X8,"") | N8: =IF($E8="","",SUMIFS('Rateio Anexo'!$K$6:$K$600,'Rateio Anexo'!$D$6:$D$600,$B8,'Rateio Anexo'!$B$6:$B$600,"MAT")) | O8: =IF($E8="","",SUMIFS('Rateio Anexo'!$K$6:$K$600,'Rateio Anexo'!$D$6:$D$600,$B8,'Rateio Anexo'!$B$6:$B$600,"MO")) | P8: =IF($E8="","",IF($N$3=0,0,N8/$N$3*$R$4)) | Q8: =IF($E8="","",IF($O$3=0,0,O8/$O$3*$T$4)) | R8: =IF($E8="","",N8+O8+P8+Q8) | S8: =IF($E8="","",(N8+P8)*Precificação!$B$19) | T8: =IF($E8="","",(O8+Q8)*Precificação!$B$20) | U8: =IF($E8="","",IF($E8=INT($E8),0.01,IF($E8*2=INT($E8*2),0.02,0.05))) | V8: =IF($E8="","",ROUND(S8/$E8/U8,0)*U8) | W8: =IF($E8="","",ROUND(T8/$E8/U8,0)*U8) | X8: =IF(NOT(ISNUMBER(E8)),"",IF(NOT(ISNUMBER(E9)),ROW(),X9))
A9: 1 | B9: A.1 | C9: Estrutura metálica para reforço da instalação de obra no painel (P05) Detalhes técnicos na prancha 2 do Projeto expografico | F9: =IF($E9="","",V9) | G9: =IF($E9="","",ROUND(W9+IF($B9=Precificação!$B$26,$F$3/$E9,0),2)) | H9: =IF($E9="","",F9+G9) | I9: =IF($E9="","",$E9*F9) | J9: =IF($E9="","",$E9*G9) | K9: =IF($E9="","",I9+J9) | L9: =IF($E9="","",IF(R9=0,"SEM CUSTO — falta linha de custo","OK")) | M9: =IF(AND(ISNUMBER(E9),NOT(ISNUMBER(E8))),"F"&ROW()&":G"&X9,"") | N9: =IF($E9="","",SUMIFS('Rateio Anexo'!$K$6:$K$600,'Rateio Anexo'!$D$6:$D$600,$B9,'Rateio Anexo'!$B$6:$B$600,"MAT")) | O9: =IF($E9="","",SUMIFS('Rateio Anexo'!$K$6:$K$600,'Rateio Anexo'!$D$6:$D$600,$B9,'Rateio Anexo'!$B$6:$B$600,"MO")) | P9: =IF($E9="","",IF($N$3=0,0,N9/$N$3*$R$4)) | Q9: =IF($E9="","",IF($O$3=0,0,O9/$O$3*$T$4)) | R9: =IF($E9="","",N9+O9+P9+Q9) | S9: =IF($E9="","",(N9+P9)*Precificação!$B$19) | T9: =IF($E9="","",(O9+Q9)*Precificação!$B$20) | U9: =IF($E9="","",IF($E9=INT($E9),0.01,IF($E9*2=INT($E9*2),0.02,0.05))) | V9: =IF($E9="","",ROUND(S9/$E9/U9,0)*U9) | W9: =IF($E9="","",ROUND(T9/$E9/U9,0)*U9) | X9: =IF(NOT(ISNUMBER(E9)),"",IF(NOT(ISNUMBER(E10)),ROW(),X10))
A10: 2 | B10: A.1.1 | C10: Molduras metálicas de 37x93cm, feitas com barra de metalon de 50x50mm, formando uma moldura chumbada em uma caixa de marcenaria com estrutura metálica interna, reforços e contrapesos. A peça deve ser feita exatamente na largura do barco, para que ele possa entrar nesse espaço da moldura e ficar fixo apenas pela pressão exercida para travá-lo. Ainda é preciso avaliar se será permitida alguma furação ou ponto de fixação no barco/obra de arte. | D10: unid | E10: 2 | F10: =IF($E10="","",V10) -> 3836.47 | G10: =IF($E10="","",ROUND(W10+IF($B10=Precificação!$B$26,$F$3/$E10,0),2)) -> 1240.75 | H10: =IF($E10="","",F10+G10) -> 5077.22 | I10: =IF($E10="","",$E10*F10) -> 7672.94 | J10: =IF($E10="","",$E10*G10) -> 2481.5 | K10: =IF($E10="","",I10+J10) -> 10154.44 | L10: =IF($E10="","",IF(R10=0,"SEM CUSTO — falta linha de custo","OK")) -> OK | M10: =IF(AND(ISNUMBER(E10),NOT(ISNUMBER(E9))),"F"&ROW()&":G"&X10,"") -> F10:G13 | N10: =IF($E10="","",SUMIFS('Rateio Anexo'!$K$6:$K$600,'Rateio Anexo'!$D$6:$D$600,$B10,'Rateio Anexo'!$B$6:$B$600,"MAT")) -> 4010 | O10: =IF($E10="","",SUMIFS('Rateio Anexo'!$K$6:$K$600,'Rateio Anexo'!$D$6:$D$600,$B10,'Rateio Anexo'!$B$6:$B$600,"MO")) -> 1284.0635 | P10: =IF($E10="","",IF($N$3=0,0,N10/$N$3*$R$4)) -> 14.34806 | Q10: =IF($E10="","",IF($O$3=0,0,O10/$O$3*$T$4)) -> 266.34304 | R10: =IF($E10="","",N10+O10+P10+Q10) -> 5574.7546 | S10: =IF($E10="","",(N10+P10)*Precificação!$B$19) -> 7672.9449 | T10: =IF($E10="","",(O10+Q10)*Precificação!$B$20) -> 2481.4947 | U10: =IF($E10="","",IF($E10=INT($E10),0.01,IF($E10*2=INT($E10*2),0.02,0.05))) -> 0.01 | V10: =IF($E10="","",ROUND(S10/$E10/U10,0)*U10) -> 3836.47 | W10: =IF($E10="","",ROUND(T10/$E10/U10,0)*U10) -> 1240.75 | X10: =IF(NOT(ISNUMBER(E10)),"",IF(NOT(ISNUMBER(E11)),ROW(),X11)) -> 13
